Workbook

Sheet 作業用シート
C2: 気球上昇速度 | J2: オレンジ色部分に入力のこと
F3: 気球種類[g] | G3: 上速度係数
D4: v. : 上昇速度 | F4: 1000 | G4: 140
D5: k. : 上昇速度係数 | F5: 1200 | G5: 140
D6: L : 浮力 | F6: 1500 | G6: 140
D7: W: 気球の重さ | F7: 2000 | G7: 150
C8: ヘリウム体積×1.114 - （気球とペイロードの重さ）[kg] | D8: 0℃1気圧での浮力L | F8: 3000 | G8: 158 | J8: 気球高度 | K8: 気球膜厚 | L8: 気球高度 | M8: 気球膜厚
C9: 気球製作所の上速度係数は本計算式だと23.6で割る必要あり | F9: 4200 | G9: 168 | J9: ='破裂高度計算（変更不可）'!A5 -> 40 | K9: ='破裂高度計算（変更不可）'!G5 -> 2.7993631 | L9: ='破裂高度計算（変更不可）'!A14 -> 29 | M9: ='破裂高度計算（変更不可）'!G14 -> 8.012289
J10: ='破裂高度計算（変更不可）'!A6 -> 35 | K10: ='破裂高度計算（変更不可）'!G6 -> 4.4453109 | L10: ='破裂高度計算（変更不可）'!A15 -> 28.75 | M10: ='破裂高度計算（変更不可）'!G15 -> 7.8563221
C11: 0℃での設計ヘリウム量 入力→ | D11: 5000 | E11: ℓ | F11: L[kg]= | G11: =D11/1000*1.114-D14/1000-D12/1000 -> 2.07 | J11: ='破裂高度計算（変更不可）'!A7 -> 32.2 | K11: ='破裂高度計算（変更不可）'!G7 -> 5.8306584 | L11: ='破裂高度計算（変更不可）'!A16 -> 28.5 | M11: ='破裂高度計算（変更不可）'!G16 -> 8.0491272
C12: 気球種類 選択→ | D12: 1500 | E12: g | F12: W[kg]= | G12: =D14/1000 -> 2 | J12: ='破裂高度計算（変更不可）'!A8 -> 30.5 | K12: ='破裂高度計算（変更不可）'!G8 -> 6.431764 | L12: ='破裂高度計算（変更不可）'!A17 -> 28.25 | M12: ='破裂高度計算（変更不可）'!G17 -> 8.2396501
C13: 上昇係数 | D13: =LOOKUP(D12,F4:F9,G4:G9) -> 140 | J13: ='破裂高度計算（変更不可）'!A9 -> 30.25 | K13: ='破裂高度計算（変更不可）'!G9 -> 6.6444081 | L13: ='破裂高度計算（変更不可）'!A18 -> 28 | M13: ='破裂高度計算（変更不可）'!G18 -> 8.8574543
C14: 気球以外の全重 入力→ | D14: 2000 | E14: g | J14: ='破裂高度計算（変更不可）'!A10 -> 30 | K14: ='破裂高度計算（変更不可）'!G10 -> 7.2509159 | L14: ='破裂高度計算（変更不可）'!A19 -> 26 | M14: ='破裂高度計算（変更不可）'!G19 -> 10.840967
C15: 速度計算結果 | D15: =G4/23.6*G11^(1/2)/(G12+G11)^(1/3) -> 5.3456814 | E15: m/s | J15: ='破裂高度計算（変更不可）'!A11 -> 29.75 | K15: ='破裂高度計算（変更不可）'!G11 -> 7.0598476 | L15: ='破裂高度計算（変更不可）'!A20 -> 23.5 | M15: ='破裂高度計算（変更不可）'!G20 -> 13.378608
C16: 破裂予測高度 | D16: 右表5μm膜厚参照 | F16: s | J16: ='破裂高度計算（変更不可）'!A12 -> 29.5 | K16: ='破裂高度計算（変更不可）'!G12 -> 7.263026 | L16: ='破裂高度計算（変更不可）'!A21 -> 22 | M16: ='破裂高度計算（変更不可）'!G21 -> 16.335083
J17: ='破裂高度計算（変更不可）'!A13 -> 29.25 | K17: ='破裂高度計算（変更不可）'!G13 -> 7.463401 | L17: ='破裂高度計算（変更不可）'!A22 -> 20.5 | M17: ='破裂高度計算（変更不可）'!G22 -> 18.806592 | N17: 5μmが破裂ライン
C19: PERC成層圏気球用ヘリウムガス量計算シート
C22: 設定値 | F22: 備考
C23: ガスボンベ容積 | D23: 47 | E23: ℓ | F23: ガスボンベの刻印を確認すること，複数ボンベを使う場合は平均容積を入れる
C24: 気球内圧力 | D24: 1013 | E24: hPa | F24: 通常は大気圧と同じで良い．気球内圧を測定している場合はその値
C25: 大気圧 | D25: 1013 | E25: hPa | F25: 当日の大気圧をできるだけ正確に
C26: 気球の中に入れたいガス量 | D26: =D11 -> 5000 | E26: ℓ | F26: ゴム気球の設計書を確認すること
C27: 気球の設計時の温度 | D27: 0 | E27: ℃
C28: 外気温 | D28: 10 | E28: ℃ | F28: 気球に入れたいガス量を設計したときの温度
C29: 高圧ガスボンベ内に残す圧力 | D29: 0.2 | E29: MPa | F29: 少なくとも0.2MPa以上は残して返却すること．2MPa以下はかなり時間がかかる
C32: 計算値 | F32: 備考
C33: 入れなければならないガス量 | D33: ='計算用シート（変更不可）'!C29 -> 5183.0496 | E33: ℓ | F33: その日の気温及び気球ない圧力を考慮したガス量
C34: 必要となるボンベ本数 | D34: ='計算用シート（変更不可）'!C30 -> 0.80743129 | E34: 本
C35: 端数ボンベ内の残圧 | D35: ='計算用シート（変更不可）'!C31 -> 3.1036122 | E35: MPa | F35: ボンベ1次圧力を確認するときは一端ガスを止めてから確認すること

Sheet 計算用シート（変更不可）
B2: 圧縮ガス封入量計算シート
B4: PV=nRT
B5: ※断熱圧縮
B6: 圧力容器ガス封入量V2=容器の容積V1*(封入圧P2/大気圧P1)*((273.15+封入温度T2)/(273.15+大気圧温度T1))
N7: 入れたいガス量がV1 | T7: 断熱圧縮 | V7: T1/T2=(V2/V1)^k-1 | X7: 表 主な気体のｍ （概略値） と比熱比γ
B8: V1 | C8: ='作業用シート'!D23 -> 47 | D8: L | E8: 1000L=1m3 | K8: P2 | L8: V3 | N8: V1 | O8: =C25 -> 5000 | P8: L | Q8: 1000L=1m3
B9: V1 | C9: =C8/1000 -> 0.047 | D9: m3 | K9: 0.1 | L9: =6813.6-((($C$9/10^9)*(K9/$C$11)*((273.15+$C$12)/(273.15+$C$13)))*10^3)*10^9 -> 6768.8418 | N9: V1 | O9: =O8/1000 -> 5 | P9: m3 | T9: T1 | U9: 0 | V9: ℃ | W9: 設計時温度 | X9: 物質名 | Y9: 化学式 | Z9: ｍ (g/mol) | AA9: 比熱比γ
B10: P2 | C10: =C27 -> 0.2 | D10: MPa | K10: 0.2 | L10: =6813.6-((($C$9/10^9)*(K10/$C$11)*((273.15+$C$12)/(273.15+$C$13)))*10^3)*10^9 -> 6724.0835 | N10: P2 | O10: =C23 -> 0.1013 | P10: MPa | Q10: 気球内圧力 | T10: T2 | U10: 10 | V10: ℃ | W10: 外気温 | X10: 水素 | Y10: H2 | Z10: 2 | AA10: 1.41
B11: P1 | C11: =C24 -> 0.1013 | D11: MPa | E11: 0.101325MPa | K11: 0.3 | L11: =6813.6-((($C$9/10^9)*(K11/$C$11)*((273.15+$C$12)/(273.15+$C$13)))*10^3)*10^9 -> 6679.3253 | N11: P1 | O11: =C24 -> 0.1013 | P11: MPa | Q11: 0.101325MPa | R11: 大気圧 | T11: V1 | U11: 12000 | V11: L | W11: 入れたい量 | X11: ヘリウム | Y11: He | Z11: 4 | AA11: 1.67
B12: T2 | C12: =C26 -> 0 | D12: ℃ | K12: 0.4 | L12: =6813.6-((($C$9/10^9)*(K12/$C$11)*((273.15+$C$12)/(273.15+$C$13)))*10^3)*10^9 -> 6634.567 | N12: T2 | O12: =C28 -> 10 | P12: ℃ | Q12: その時の外気温 | T12: V2 | U12: =U11*((273.15+U9)/(273.15+U10))^(1/(AA11-1)) -> 11372.992 | V12: L | W12: 実際の量 | X12: 窒素 | Y12: N2 | Z12: 28 | AA12: 1.4
B13: T1 | C13: =C28 -> 10 | D13: ℃ | K13: 0.5 | L13: =6813.6-((($C$9/10^9)*(K13/$C$11)*((273.15+$C$12)/(273.15+$C$13)))*10^3)*10^9 -> 6589.8088 | N13: T1 | O13: =C26 -> 0 | P13: ℃ | Q13: 設計時の温度 | X13: 酸素 | Y13: O2 | Z13: 32 | AA13: 1.4
K14: 0.6 | L14: =6813.6-((($C$9/10^9)*(K14/$C$11)*((273.15+$C$12)/(273.15+$C$13)))*10^3)*10^9 -> 6545.0505 | T14: その差 | U14: =U11-U12 -> 627.00791 | V14: L | X14: 二酸化炭素 | Y14: CO2 | Z14: 44 | AA14: 1.29
B15: V2 | C15: =((C9/10^9)*(C10/C11)*((273.15+C12)/(273.15+C13)))*10^3 -> 8.951649e-08 | D15: cm3 | K15: 0.7 | L15: =6813.6-((($C$9/10^9)*(K15/$C$11)*((273.15+$C$12)/(273.15+$C$13)))*10^3)*10^9 -> 6500.2923 | N15: V2 | O15: =((O9/10^9)*(O10/O11)*((273.15+O12)/(273.15+O13)))*10^3 -> 5.1830496e-06 | P15: cm3 | X15: 空気 | Y15: - | Z15: 28.96 | AA15: 1.4
B16: V2 | C16: =C15*10^6 -> 0.08951649 | D16: m3 | K16: 0.8 | L16: =6813.6-((($C$9/10^9)*(K16/$C$11)*((273.15+$C$12)/(273.15+$C$13)))*10^3)*10^9 -> 6455.534 | N16: V2 | O16: =O15*10^6 -> 5.1830496 | P16: m3 | T16: V1/T1=V2/T2
B17: V2 | C17: =C16*10^3 -> 89.51649 | D17: L | E17: 47Lボンベ内の残量 | K17: 0.9 | L17: =6813.6-((($C$9/10^9)*(K17/$C$11)*((273.15+$C$12)/(273.15+$C$13)))*10^3)*10^9 -> 6410.7758 | N17: V2 | O17: =O16*10^3 -> 5183.0496 | P17: L | Q17: 実験時の外気温でのボリューム | T17: V2=T2V1/T1
K18: 1 | L18: =6813.6-((($C$9/10^9)*(K18/$C$11)*((273.15+$C$12)/(273.15+$C$13)))*10^3)*10^9 -> 6366.0175
B19: V3 | C19: =6508.7-C17 -> 6419.1835 | D19: L | E19: 47Lボンベの使用量 | K19: 1.1 | L19: =6813.6-((($C$9/10^9)*(K19/$C$11)*((273.15+$C$12)/(273.15+$C$13)))*10^3)*10^9 -> 6321.2593 | N19: 差 | O19: =O17-O8 -> 183.04961 | P19: L | Q19: 設計時との差 | T19: V2 | U19: =(273.15+U10)*U11/(273.15+U9) -> 12439.319 | V19: L
K20: 1.2 | L20: =6813.6-((($C$9/10^9)*(K20/$C$11)*((273.15+$C$12)/(273.15+$C$13)))*10^3)*10^9 -> 6276.5011
B21: V | C21: =C19+C17 -> 6508.7 | D21: L | E21: 47Lボンベの容量 | K21: 1.3 | L21: =6813.6-((($C$9/10^9)*(K21/$C$11)*((273.15+$C$12)/(273.15+$C$13)))*10^3)*10^9 -> 6231.7428 | T21: その差 | U21: =U19-U11 -> 439.31906 | V21: L
G22: V2/V1=P2/P1*T2/T1 | K22: 1.4 | L22: =6813.6-((($C$9/10^9)*(K22/$C$11)*((273.15+$C$12)/(273.15+$C$13)))*10^3)*10^9 -> 6186.9846
B23: 気球内圧力 | C23: ='作業用シート'!D24*10^-4 -> 0.1013 | D23: MPa | E23: 大気圧で普段はOK | G23: P2=V2/V1*P1*T1/T2 | K23: 1.5 | L23: =6813.6-((($C$9/10^9)*(K23/$C$11)*((273.15+$C$12)/(273.15+$C$13)))*10^3)*10^9 -> 6142.2263
B24: 大気圧 | C24: ='作業用シート'!D25*10^-4 -> 0.1013 | D24: MPa | K24: 1.6 | L24: =6813.6-((($C$9/10^9)*(K24/$C$11)*((273.15+$C$12)/(273.15+$C$13)))*10^3)*10^9 -> 6097.4681
B25: 入れたいガス量 | C25: ='作業用シート'!D26 -> 5000 | D25: L | F25: =C21-(O17-(ROUNDDOWN(C30,0.1)*C19)) -> 1325.6504 | K25: 1.7 | L25: =6813.6-((($C$9/10^9)*(K25/$C$11)*((273.15+$C$12)/(273.15+$C$13)))*10^3)*10^9 -> 6052.7098
B26: 設計時の温度 | C26: ='作業用シート'!D27 -> 0 | D26: ℃ | F26: =14.7-(1/(((C9/10^9)*(1/C11)*((273.15+C12)/(273.15+C13))*(F25/10^9))*10^3))/10^12 -> 13.01462 | G26: =(F25/C21)*14.7*((273.15+C13)/(273.15+C12)) -> 3.1036122 | K26: 1.8 | L26: =6813.6-((($C$9/10^9)*(K26/$C$11)*((273.15+$C$12)/(273.15+$C$13)))*10^3)*10^9 -> 6007.9516
B27: ボンベ内に残す圧力 | C27: ='作業用シート'!D29 -> 0.2 | D27: MPa | K27: 1.9 | L27: =6813.6-((($C$9/10^9)*(K27/$C$11)*((273.15+$C$12)/(273.15+$C$13)))*10^3)*10^9 -> 5963.1933
B28: 外気温 | C28: ='作業用シート'!D28 -> 10 | D28: ℃ | K28: 2 | L28: =6813.6-((($C$9/10^9)*(K28/$C$11)*((273.15+$C$12)/(273.15+$C$13)))*10^3)*10^9 -> 5918.4351
B29: 入れなければならないガス量 | C29: =O17 -> 5183.0496 | D29: L | K29: 2.1 | L29: =6813.6-((($C$9/10^9)*(K29/$C$11)*((273.15+$C$12)/(273.15+$C$13)))*10^3)*10^9 -> 5873.6768
B30: ボンベ本数 | C30: =O17/C19 -> 0.80743129 | D30: 本 | K30: 2.2 | L30: =6813.6-((($C$9/10^9)*(K30/$C$11)*((273.15+$C$12)/(273.15+$C$13)))*10^3)*10^9 -> 5828.9186
B31: 残圧 | C31: =(F25/C21)*14.7*((273.15+C13)/(273.15+C12)) -> 3.1036122 | D31: Mpa | K31: 2.3 | L31: =6813.6-((($C$9/10^9)*(K31/$C$11)*((273.15+$C$12)/(273.15+$C$13)))*10^3)*10^9 -> 5784.1604
K32: 2.4 | L32: =6813.6-((($C$9/10^9)*(K32/$C$11)*((273.15+$C$12)/(273.15+$C$13)))*10^3)*10^9 -> 5739.4021
K33: 2.5 | L33: =6813.6-((($C$9/10^9)*(K33/$C$11)*((273.15+$C$12)/(273.15+$C$13)))*10^3)*10^9 -> 5694.6439
K34: 2.6 | L34: =6813.6-((($C$9/10^9)*(K34/$C$11)*((273.15+$C$12)/(273.15+$C$13)))*10^3)*10^9 -> 5649.8856
K35: 2.7 | L35: =6813.6-((($C$9/10^9)*(K35/$C$11)*((273.15+$C$12)/(273.15+$C$13)))*10^3)*10^9 -> 5605.1274
K36: 2.8 | L36: =6813.6-((($C$9/10^9)*(K36/$C$11)*((273.15+$C$12)/(273.15+$C$13)))*10^3)*10^9 -> 5560.3691
K37: 2.9 | L37: =6813.6-((($C$9/10^9)*(K37/$C$11)*((273.15+$C$12)/(273.15+$C$13)))*10^3)*10^9 -> 5515.6109
K38: 3 | L38: =6813.6-((($C$9/10^9)*(K38/$C$11)*((273.15+$C$12)/(273.15+$C$13)))*10^3)*10^9 -> 5470.8526
K39: 3.1 | L39: =6813.6-((($C$9/10^9)*(K39/$C$11)*((273.15+$C$12)/(273.15+$C$13)))*10^3)*10^9 -> 5426.0944
K40: 3.2 | L40: =6813.6-((($C$9/10^9)*(K40/$C$11)*((273.15+$C$12)/(273.15+$C$13)))*10^3)*10^9 -> 5381.3362
K41: 3.3 | L41: =6813.6-((($C$9/10^9)*(K41/$C$11)*((273.15+$C$12)/(273.15+$C$13)))*10^3)*10^9 -> 5336.5779
K42: 3.4 | L42: =6813.6-((($C$9/10^9)*(K42/$C$11)*((273.15+$C$12)/(273.15+$C$13)))*10^3)*10^9 -> 5291.8197
...

Sheet 破裂高度計算（変更不可）
A3: 高度(km) | B3: 標準大気圧 | C3: 超高層大気圧 | D3: 体積膨張率 | E3: 表面積膨張率 | F3: 標準厚さ | G3: 装填時厚さ
I4: 標準体積 | J4: 装填体積
A5: 40 | C5: 2.8714 | D5: =B$29/C5 -> 352.87658 | E5: =(D5^2)^(1/3) -> 49.93617 | F5: =130/E5 -> 2.6033234 | G5: =F5/$J$7 -> 2.7993631 | I5: =LOOKUP('作業用シート'!D12,L17:L21,N17:N21) -> 5575.2798 | J5: ='作業用シート'!D11 -> 5000
A6: 35 | C6: 5.7459 | D6: =B$29/C6 -> 176.3431 | E6: =(D6^2)^(1/3) -> 31.4465 | F6: =130/E6 -> 4.1340054 | G6: =F6/$J$7 -> 4.4453109 | I6: 体積膨張 | J6: 表面積膨張
A7: 32.2 | C7: 8.6314 | D7: =B$29/C7 -> 117.39113 | E7: =(D7^2)^(1/3) -> 23.974903 | F7: =130/E7 -> 5.4223368 | G7: =F7/$J$7 -> 5.8306584 | I7: =J5/I5 -> 0.89681598 | J7: =(I7^2)^(1/3) -> 0.9299699
A8: 30.5 | C8: 10 | D8: =B$29/C8 -> 101.32498 | E8: =(D8^2)^(1/3) -> 21.734235 | F8: =130/E8 -> 5.9813469 | G8: =F8/$J$7 -> 6.431764
A9: 30.25 | C9: 10.5 | D9: =B$29/C9 -> 96.499983 | E9: =(D9^2)^(1/3) -> 21.038664 | F9: =130/E9 -> 6.1790996 | G9: =F9/$J$7 -> 6.6444081
A10: 30 | C10: 11.97 | D10: =B$29/C10 -> 84.649108 | E10: =(D10^2)^(1/3) -> 19.278871 | F10: =130/E10 -> 6.7431335 | G10: =F10/$J$7 -> 7.2509159
A11: 29.75 | C11: 11.5 | D11: =B$29/C11 -> 88.10868 | E11: =(D11^2)^(1/3) -> 19.800636 | F11: =130/E11 -> 6.5654458 | G11: =F11/$J$7 -> 7.0598476
A12: 29.5 | C12: 12 | D12: =B$29/C12 -> 84.437485 | E12: =(D12^2)^(1/3) -> 19.246726 | F12: =130/E12 -> 6.7543956 | G12: =F12/$J$7 -> 7.263026
A13: 29.25 | C13: 12.5 | D13: =B$29/C13 -> 81.059986 | E13: =(D13^2)^(1/3) -> 18.729996 | F13: =130/E13 -> 6.9407383 | G13: =F13/$J$7 -> 7.463401
A14: 29 | C14: 13.904 | D14: =B$29/C14 -> 72.8747 | E14: =(D14^2)^(1/3) -> 17.446883 | F14: =130/E14 -> 7.4511876 | G14: =F14/$J$7 -> 8.012289
A15: 28.75 | C15: 13.5 | D15: =B$29/C15 -> 75.055543 | E15: =(D15^2)^(1/3) -> 17.793246 | F15: =130/E15 -> 7.3061431 | G15: =F15/$J$7 -> 7.8563221
A16: 28.5 | C16: 14 | D16: =B$29/C16 -> 72.374988 | E16: =(D16^2)^(1/3) -> 17.367035 | F16: =130/E16 -> 7.485446 | G16: =F16/$J$7 -> 8.0491272 | L16: 品名 | M16: 直径（長さ）[m] | N16: 標準体積[ℓ] | O16: 標準表面積[m2]
A17: 28.25 | C17: 14.5 | D17: =B$29/C17 -> 69.879298 | E17: =(D17^2)^(1/3) -> 16.965462 | F17: =130/E17 -> 7.6626266 | G17: =F17/$J$7 -> 8.2396501 | L17: 1000 | M17: 1.8 | N17: =PI()*M17^3/6*1000 -> 3053.6281 | O17: =PI()*M17^2 -> 10.17876
A18: 28 | C18: 16.161 | D18: =B$29/C18 -> 62.697223 | E18: =(D18^2)^(1/3) -> 15.782127 | F18: =130/E18 -> 8.2371659 | G18: =F18/$J$7 -> 8.8574543 | L18: 1200 | M18: 2 | N18: =PI()*M18^3/6*1000 -> 4188.7902 | O18: =PI()*M18^2 -> 12.566371
A19: 26 | C19: 21.883 | D19: =B$29/C19 -> 46.303058 | E19: =(D19^2)^(1/3) -> 12.894558 | F19: =130/E19 -> 10.081773 | G19: =F19/$J$7 -> 10.840967 | L19: 1500 | M19: 2.2 | N19: =PI()*M19^3/6*1000 -> 5575.2798 | O19: =PI()*M19^2 -> 15.205308
A20: 23.5 | C20: 30 | D20: =B$29/C20 -> 33.774994 | E20: =(D20^2)^(1/3) -> 10.44873 | F20: =130/E20 -> 12.441703 | G20: =F20/$J$7 -> 13.378608 | L20: 2000 | M20: 2.5 | N20: =PI()*M20^3/6*1000 -> 8181.2309 | O20: =PI()*M20^2 -> 19.634954
A21: 22 | C21: 40.475 | D21: =B$29/C21 -> 25.033967 | E21: =(D21^2)^(1/3) -> 8.5576224 | F21: =130/E21 -> 15.191135 | G21: =F21/$J$7 -> 16.335083 | L21: 3000 | M21: 2.95 | N21: =PI()*M21^3/6*1000 -> 13442.024 | O21: =PI()*M21^2 -> 27.33971
A22: 20.5 | C22: 50 | D22: =B$29/C22 -> 20.264996 | E22: =(D22^2)^(1/3) -> 7.4330038 | F22: =130/E22 -> 17.489565 | G22: =F22/$J$7 -> 18.806592
A23: 18 | B23: =((44.331514-A23)/11.880516)^5.255877 -> 65.560778 | D23: =B$29/B23 -> 15.455122 | E23: =(D23^2)^(1/3) -> 6.2046167 | F23: =130/E23 -> 20.95214 | G23: =F23/$J$7 -> 22.529912
A24: 16 | B24: =((44.331514-A24)/11.880516)^5.255877 -> 96.327259 | D24: =B$29/B24 -> 10.518828 | E24: =(D24^2)^(1/3) -> 4.8007773 | F24: =130/E24 -> 27.078948 | G24: =F24/$J$7 -> 29.118091 | L24: ゴム気球の厚さは130μm、5μmになると割れる
A25: 15 | B25: =((44.331514-A25)/11.880516)^5.255877 -> 115.5919 | D25: =B$29/B25 -> 8.7657512 | E25: =(D25^2)^(1/3) -> 4.2513425 | F25: =130/E25 -> 30.578576 | G25: =F25/$J$7 -> 32.881253
A26: 13.5 | B26: =((44.331514-A26)/11.880516)^5.255877 -> 150.23518 | D26: =B$29/B26 -> 6.7444245 | E26: =(D26^2)^(1/3) -> 3.5696853 | F26: =130/E26 -> 36.417776 | G26: =F26/$J$7 -> 39.160166
A27: 12.7 | B27: =((44.331514-A27)/11.880516)^5.255877 -> 171.88736 | D27: =B$29/B27 -> 5.8948477 | E27: =(D27^2)^(1/3) -> 3.2632353 | F27: =130/E27 -> 39.837764 | G27: =F27/$J$7 -> 42.837692
A28: 12 | B28: =((44.331514-A28)/11.880516)^5.255877 -> 192.84423 | D28: =B$29/B28 -> 5.2542399 | E28: =(D28^2)^(1/3) -> 3.0223164 | F28: =130/E28 -> 43.013365 | G28: =F28/$J$7 -> 46.252427
A29: 0 | B29: =((44.331514-A29)/11.880516)^5.255877 -> 1013.2498 | D29: =B$29/B29 -> 1 | E29: 1 | F29: 130 | G29: =F29/$J$7 -> 139.78947
